Workbook

Sheet info
B2: version | C2: 1.3.1
B3: notice | C3: 이제는 직접민주주의로 참여하는 시대입니다. 다양한 방법으로 지역구 의원이 무슨일을 하는지 확인하고 잘하면 칭찬하고 못하면 비판하며 때로는 토론도 해보세요.
B4: notice_date | C4: 03/27/21
B5: patch | C5: 1. 의원직 변경 적용

Sheet congressman
B2: no | C2: name | D2: title | E2: group | F2: field | G2: mobile | H2: office_asm | I2: office_area | J2: email | K2: twitter | L2: facebook | M2: kakao | N2: instagram | O2: youtube | P2: web | Q2: blog | R2: cafe | S2: cyworld | T2: assembly | U2: assembly_no | V2: sponsor
A3: * | B3: 1 | C3: 강병원 | D3: 국회의원 | E3: =groups!$B$3 -> 1 | F3: 서울 은평 을 | H3: 02-784-1422 | J3: kangbw89@gmail.com | K3: kbw89 | L3: 100001968500108 | O3: https://www.youtube.com/channel/UCRqhzBrMh6LIn9-LIbFLMEw | P3: http://blog.naver.com/kangbw89 | T3: 9770933 | U3: 2888 | V3: 201700001 | W3: =CONCAT(CONCAT("https://assembly.go.kr/photo/", T3), ".jpg") -> https://assembly.go.kr/photo/9770933.jpg
A4: * | B4: 2 | C4: 강선우 | D4: 국회의원 | E4: =groups!$B$3 -> 1 | F4: 서울 강서 갑 | H4: 02-6788-6031,02-6788-6032,02-6788-6033,02-6788-6034 | J4: gangseo.kap@gmail.com | L4: 100023491010959 | P4: http://blog.naver.com/gangseo-kap | T4: 9771116 | U4: 155 | V4: 201700002 | W4: =CONCAT(CONCAT("https://assembly.go.kr/photo/", T4), ".jpg") -> https://assembly.go.kr/photo/9771116.jpg
A5: * | B5: 3 | C5: 강훈식 | D5: 국회의원 | E5: =groups!$B$3 -> 1 | F5: 충남 아산 을 | H5: 02-784-1045 | J5: gohoonsik@gmail.com | L5: 100008672748962 | N5: gohoonsik | O5: https://www.youtube.com/watch?v=DXKNIADDQ8E | P5: http://blog.naver.com/kanghunsik | T5: 9771007 | U5: 2853 | V5: 201700003 | W5: =CONCAT(CONCAT("https://assembly.go.kr/photo/", T5), ".jpg") -> https://assembly.go.kr/photo/9771007.jpg
A6: * | B6: 4 | C6: 고용진 | D6: 국회의원 | E6: =groups!$B$3 -> 1 | F6: 서울 노원 갑 | H6: 02-784-4840 | I6: 02-941-0413 | J6: gogoyongjin@naver.com | K6: yongjin_koh | L6: 100002728329388 | O6: https://www.youtube.com/watch?v=7qTR-KKkh4U | P6: http://blog.naver.com/kohyj64 | T6: 9770931 | U6: 2951 | V6: 201700004 | W6: =CONCAT(CONCAT("https://assembly.go.kr/photo/", T6), ".jpg") -> https://assembly.go.kr/photo/9770931.jpg
A7: * | B7: 5 | C7: 강득구 | D7: 국회의원 | E7: =groups!$B$3 -> 1 | F7: 경기 안양 만안 | H7: 02-784-7727 | K7: https://mobile.twitter.com/deukgu_kang | L7: 100006255608922 | N7: https://www.instagram.com/deukgu_kang/ | O7: https://www.youtube.com/channel/UCWPYeOndgzUJ2atd1NwpBTw | Q7: https://blog.naver.com/dulipapa | T7: 9771174 | U7: 2845 | V7: 201700005 | W7: =CONCAT(CONCAT("https://assembly.go.kr/photo/", T7), ".jpg") -> https://assembly.go.kr/photo/9771174.jpg
A8: * | B8: 6 | C8: 권칠승 | D8: 국회의원 | E8: =groups!$B$3 -> 1 | F8: 경기 화성 병 | H8: 02-784-1250 | I8: 031-222-0110 | K8: k7win_ | L8: 100011077455328 | N8: chil_seung | O8: https://www.youtube.com/watch?v=Nz5cDRZ4EBA | P8: http://blog.naver.com/k7wins | T8: 9770998 | U8: 2841 | V8: 201700006 | W8: =CONCAT(CONCAT("https://assembly.go.kr/photo/", T8), ".jpg") -> https://assembly.go.kr/photo/9770998.jpg
A9: * | B9: 7 | C9: 강준현 | D9: 국회의원 | E9: =groups!$B$3 -> 1 | F9: 세종 을 | H9: 02-784-6950 | J9: jhkang315@gmail.com | L9: 100001832977624 | P9: https://blog.naver.com/withusone2020 | T9: 9771168 | U9: 2849 | V9: 201700007 | W9: =CONCAT(CONCAT("https://assembly.go.kr/photo/", T9), ".jpg") -> https://assembly.go.kr/photo/9771168.jpg
A10: * | B10: 8 | C10: 기동민 | D10: 국회의원 | E10: =groups!$B$3 -> 1 | F10: 서울 성북 을 | H10: 02-784-3181 | L10: 100001422477735 | O10: https://www.youtube.com/watch?v=Cjm7G1RFCkI | P10: http://blog.naver.com/gidongmin | T10: 9770927 | U10: 2967 | V10: 201700008 | W10: =CONCAT(CONCAT("https://assembly.go.kr/photo/", T10), ".jpg") -> https://assembly.go.kr/photo/9770927.jpg
A11: * | B11: 10 | C11: 김경협 | D11: 국회의원 | E11: =groups!$B$3 -> 1 | F11: 경기 부천 원미 갑 | H11: 02-784-1190 | I11: 032-666-0520 | J11: ggh000@naver.com | K11: kimghkr | L11: 100000942849824 | O11: https://www.youtube.com/channel/UCcheolAyghSDXGsilCbg3WA | P11: http://www.kimgh.com | Q11: http://blog.naver.com/ggh000/ | T11: 9770712 | U11: 2606 | V11: 201700010 | W11: =CONCAT(CONCAT("https://assembly.go.kr/photo/", T11), ".jpg") -> https://assembly.go.kr/photo/9770712.jpg
A12: * | B12: 11 | C12: 김두관 | D12: 국회의원 | E12: =groups!$B$3 -> 1 | F12: 경기 김포 갑 | H12: 02-784-2566 | I12: 031-997-6840 | K12: dookwan | L12: 181899161847606 | O12: https://www.youtube.com/watch?v=a3SrEeUxPj0 | P12: http://okdk.kr/ | Q12: http://blog.naver.com/kikdok | T12: 9770997 | U12: 2836 | V12: 201700011 | W12: =CONCAT(CONCAT("https://assembly.go.kr/photo/", T12), ".jpg") -> https://assembly.go.kr/photo/9770997.jpg
A13: * | B13: 12 | C13: 김민기 | D13: 국회의원 | E13: =groups!$B$3 -> 1 | F13: 경기 용인 을 | H13: 02-784-1930 | I13: 031-282-9940 | J13: kimminki@assembly.go.kr | K13: kimminki84 | L13: 100001360593401 | O13: https://youtu.be/wI9fxU3_vPQ | P13: http://www.kimminki.co.kr/ | Q13: http://blog.naver.com/kminki84 | T13: 9770723 | U13: 2576 | V13: 201700012 | W13: =CONCAT(CONCAT("https://assembly.go.kr/photo/", T13), ".jpg") -> https://assembly.go.kr/photo/9770723.jpg
A14: * | B14: 13 | C14: 고민정 | D14: 국회의원 | E14: =groups!$B$3 -> 1 | F14: 서울 광진 을 | L14: 100002798435881 | O14: https://www.youtube.com/channel/UC2Lx2_u4JixQ2WFnWQfIbEQ | T14: 9771109 | U14: 2858 | V14: 201700013 | W14: =CONCAT(CONCAT("https://assembly.go.kr/photo/", T14), ".jpg") -> https://assembly.go.kr/photo/9771109.jpg
A15: * | B15: 14 | C15: 김병기 | D15: 국회의원 | E15: =groups!$B$3 -> 1 | F15: 서울 동작 갑 | H15: 02-784-1322 | K15: thekimweapon | L15: 100011526436490 | N15: the.kim.weapon | O15: https://www.youtube.com/watch?v=Y6d4rRb7i4A | P15: http://kimbyungkee.kr/ | T15: 9770941 | U15: 2898 | V15: 201700014 | W15: =CONCAT(CONCAT("https://assembly.go.kr/photo/", T15), ".jpg") -> https://assembly.go.kr/photo/9770941.jpg
A16: * | B16: 15 | C16: 김병욱 | D16: 국회의원 | E16: =groups!$B$3 -> 1 | F16: 경기 성남 분당 을 | H16: 02-784-3670~2 | K16: 777byung1 | L16: 100001463493979 | N16: 777byung | O16: https://www.youtube.com/channel/UCkKmE-matF_3iwaw-Q7BjZA | P16: http://blog.naver.com/777byung | T16: 9770984 | U16: 2928 | V16: 201700015 | W16: =CONCAT(CONCAT("https://assembly.go.kr/photo/", T16), ".jpg") -> https://assembly.go.kr/photo/9770984.jpg
A17: * | B17: 16 | C17: 고영인 | D17: 국회의원 | E17: =groups!$B$3 -> 1 | F17: 경기 안산 단원 갑 | L17: 100000163239885 | T17: 9771180 | U17: 305 | V17: 201700016 | W17: =CONCAT(CONCAT("https://assembly.go.kr/photo/", T17), ".jpg") -> https://assembly.go.kr/photo/9771180.jpg
A18: * | B18: 17 | C18: 김상희 | D18: 국회의원 | E18: =groups!$B$3 -> 1 | F18: 경기 부천 소사 | H18: 02-784-4173 | J18: shk@assembly.go.kr | K18: sosakim | L18: 100002181912858 | O18: https://www.youtube.com/watch?v=ibAHWTVvzl4 | P18: http://www.cleankim.kr/ | Q18: http://blog.naver.com/shk407 | T18: 9770527 | U18: 2760 | V18: 201700017 | W18: =CONCAT(CONCAT("https://assembly.go.kr/photo/", T18), ".jpg") -> https://assembly.go.kr/photo/9770527.jpg
A19: * | B19: 18 | C19: 권인숙 | D19: 국회의원 | E19: =groups!$B$3 -> 1 | F19: 비례대표 | L19: 520949508 | T19: 9771259 | U19: 2871 | V19: 201700018 | W19: =CONCAT(CONCAT("https://assembly.go.kr/photo/", T19), ".jpg") -> https://assembly.go.kr/photo/9771259.jpg
A20: * | B20: 19 | C20: 김영주 | D20: 국회의원 | E20: =groups!$B$3 -> 1 | F20: 서울 영등포 갑 | H20: 02-784-2470 | I20: 02-2672-6712 | J20: joojoo2012@naver.com | K20: yjkim550727 | L20: 100001441525499 | O20: https://www.youtube.com/watch?v=aqfRVFnvWpo | P20: http://www.youngjoo.kr | T20: 9770975 | U20: 145 | V20: 201700019 | W20: =CONCAT(CONCAT("https://assembly.go.kr/photo/", T20), ".jpg") -> https://assembly.go.kr/photo/9770975.jpg
A21: * | B21: 20 | C21: 김영진 | D21: 국회의원 | E21: =groups!$B$3 -> 1 | F21: 경기 수원 병 | H21: 02-784-8410 | K21: minjoop | L21: 100001777896522 | M21: _anxcqd | O21: https://www.youtube.com/channel/UC6Bxiwajm3Fa4gdYTB2kB3g | P21: https://blog.naver.com/ersd34 | T21: 9770981 | U21: 2970 | V21: 201700020 | W21: =CONCAT(CONCAT("https://assembly.go.kr/photo/", T21), ".jpg") -> https://assembly.go.kr/photo/9770981.jpg
A22: * | B22: 21 | C22: 김경만 | D22: 국회의원 | E22: =groups!$B$3 -> 1 | F22: 비례대표 | H22: 02-784-9820 | J22: 2020kkman@gmail.com | L22: 100049429267021 | P22: http://blog.naver.com/2020kkman | T22: 9771258 | U22: 222 | V22: 201700021 | W22: =CONCAT(CONCAT("https://assembly.go.kr/photo/", T22), ".jpg") -> https://assembly.go.kr/photo/9771258.jpg
A23: * | B23: 22 | C23: 김영호 | D23: 국회의원 | E23: =groups!$B$3 -> 1 | F23: 서울 서대문 을 | H23: 02-784-4020~2 | J23: kim-youngho@naver.com | K23: minjoo05 | L23: 100002182712870 | N23: minjoo_kimyoungho | O23: https://www.youtube.com/channel/UCQqH7k22MywV8dmbS5MJAAQ | P23: https://blog.naver.com/frencisco | T23: 9770934 | U23: 2863 | V23: 201700022 | W23: =CONCAT(CONCAT("https://assembly.go.kr/photo/", T23), ".jpg") -> https://assembly.go.kr/photo/9770934.jpg
A24: * | B24: 23 | C24: 김교흥 | D24: 국회의원 | E24: =groups!$B$3 -> 1 | F24: 인천 서 갑 | L24: 100000646145534 | T24: 9771152 | U24: 2864 | V24: 201700023 | W24: =CONCAT(CONCAT("https://assembly.go.kr/photo/", T24), ".jpg") -> https://assembly.go.kr/photo/9771152.jpg
A25: * | B25: 24 | C25: 김종민 | D25: 국회의원 | E25: =groups!$B$3 -> 1 | F25: 충남 논산·계룡·금산 | H25: 02-784-5920 | K25: socmind | L25: 100001746723623 | O25: https://www.youtube.com/watch?v=MYS_8J8om5E | P25: https://blog.naver.com/socmind | T25: 9771009 | U25: 2833 | V25: 201700024 | W25: =CONCAT(CONCAT("https://assembly.go.kr/photo/", T25), ".jpg") -> https://assembly.go.kr/photo/9771009.jpg
A26: * | B26: 25 | C26: 김진표 | D26: 국회의원 | E26: =groups!$B$3 -> 1 | F26: 경기 수원 무 | H26: 02-784-3807 | K26: jinpyokim | L26: 100010889073617 | O26: https://www.youtube.com/user/jinpyotv | P26: http://blog.naver.com/jinpyo311 | T26: 9770982 | U26: 2775 | V26: 201700025 | W26: =CONCAT(CONCAT("https://assembly.go.kr/photo/", T26), ".jpg") -> https://assembly.go.kr/photo/9770982.jpg
A27: * | B27: 26 | C27: 김철민 | D27: 국회의원 | E27: =groups!$B$3 -> 1 | F27: 경기 안산 상록 을 | H27: 02-784-2135 | I27: 031-405-7755 | J27: kcm8764@naver.com | K27: kimcm8764 | L27: 100047248433839 | O27: https://www.youtube.com/watch?v=D9kQAUbKZ4c | P27: http://blog.naver.com/kcm8764 | T27: 9770986 | U27: 2966 | V27: 201700026 | W27: =CONCAT(CONCAT("https://assembly.go.kr/photo/", T27), ".jpg") -> https://assembly.go.kr/photo/9770986.jpg
A28: * | B28: 27 | C28: 김태년 | D28: 국회의원 | E28: =groups!$B$3 -> 1 | F28: 경기 성남 수정 | H28: 02-784-4570 | I28: 031-751-4048 | J28: ktn0320@daum.net | K28: kimtaenyeon | L28: 100002122729408 | O28: https://www.youtube.com/watch?v=NwalcMu_Bi0 | P28: http://www.ktn21.com/ | Q28: http://blog.naver.com/ktn208 | T28: 9770741 | U28: 556 | V28: 201700027 | W28: =CONCAT(CONCAT("https://assembly.go.kr/photo/", T28), ".jpg") -> https://assembly.go.kr/photo/9770741.jpg
A29: * | B29: 28 | C29: 김한정 | D29: 국회의원 | E29: =groups!$B$3 -> 1 | F29: 경기 남양주 을 | H29: 02-784-0496 | I29: 031-573-6669 | K29: hanjungok | L29: 100000513084408 | O29: https://www.youtube.com/watch?v=aHysDIgrSVY | P29: http://blog.naver.com/hanjungkim | T29: 9770991 | U29: 2931 | V29: 201700028 | W29: =CONCAT(CONCAT("https://assembly.go.kr/photo/", T29), ".jpg") -> https://assembly.go.kr/photo/9770991.jpg
A30: * | B30: 29 | C30: 김남국 | D30: 국회의원 | E30: =groups!$B$3 -> 1 | F30: 경기 안산 단원 을 | H30: 02-784-2455 | J30: lawmaker0415@daum.net | L30: 100003413637531 | O30: https://www.youtube.com/channel/UC5ylgZz6hi0eCIzAq7y5H9g | T30: 9771181 | U30: 2924 | V30: 201700029 | W30: =CONCAT(CONCAT("https://assembly.go.kr/photo/", T30), ".jpg") -> https://assembly.go.kr/photo/9771181.jpg
A31: * | B31: 30 | C31: 김민석 | D31: 국회의원 | E31: =groups!$B$3 -> 1 | F31: 서울 영등포 을 | H31: 02-784-2390 | J31: newkms2030@gmail.com | K31: ms2030 | L31: 1555220270 | P31: http://kms2030.kr | T31: 9771120 | U31: 2875 | V31: 201700030 | W31: =CONCAT(CONCAT("https://assembly.go.kr/photo/", T31), ".jpg") -> https://assembly.go.kr/photo/9771120.jpg
A32: * | B32: 31 | C32: 김민철 | D32: 국회의원 | E32: =groups!$B$3 -> 1 | F32: 경기 의정부 을 | H32: 02-784-4990 | I32: 031-925-2024 | L32: 100000957036249 | T32: 9771173 | U32: 128 | V32: 201700031 | W32: =CONCAT(CONCAT("https://assembly.go.kr/photo/", T32), ".jpg") -> https://assembly.go.kr/photo/9771173.jpg
A33: * | B33: 32 | C33: 남인순 | D33: 국회의원 | E33: =groups!$B$3 -> 1 | F33: 서울 송파 병 | H33: 02-784-5980 | J33: nisoon@na.go.kr | K33: nisoon | L33: 100000654518088 | M33: _ewwiM | N33: flynisoon | O33: https://www.youtube.com/watch?v=Ekhq13BipHk | P33: http://www.nisoon.co.kr/ | Q33: http://blog.naver.com/nisoon | T33: 9770752 | U33: 2618 | V33: 201700032 | W33: =CONCAT(CONCAT("https://assembly.go.kr/photo/", T33), ".jpg") -> https://assembly.go.kr/photo/9770752.jpg
A34: * | B34: 33 | C34: 노웅래 | D34: 국회의원 | E34: =groups!$B$3 -> 1 | F34: 서울 마포 갑 | H34: 02-788-2203 | I34: 02-3275-1664 | J34: wraenoh@hanmail.net | K34: gowith_wraenoh | L34: 100011462499036 | N34: with_wraenoh | O34: https://www.youtube.com/watch?v=iVrlv5HADq8 | P34: http://blog.naver.com/with_wraenoh | T34: 9770753 | U34: 133 | V34: 201700033 | W34: =CONCAT(CONCAT("https://assembly.go.kr/photo/", T34), ".jpg") -> https://assembly.go.kr/photo/9770753.jpg
A35: * | B35: 34 | C35: 도종환 | D35: 국회의원 | E35: =groups!$B$3 -> 1 | F35: 충북 청주 흥덕 | H35: 02-784-2537 | I35: 043-235-0300 | J35: djhpoem@assembly.go.kr | K35: djhpoem2 | L35: 100004000310066 | O35: https://www.youtube.com/watch?v=v8FS5f0dgmg | P35: http://djh333.co.kr/ | T35: 9770755 | U35: 2585 | V35: 201700034 | W35: =CONCAT(CONCAT("https://assembly.go.kr/photo/", T35), ".jpg") -> https://assembly.go.kr/photo/9770755.jpg
A36: * | B36: 35 | C36: 문정복 | D36: 국회의원 | E36: =groups!$B$3 -> 1 | F36: 경기 시흥 갑 | H36: 02-784-9850 | J36: indobangrang@hanmail.net | L36: 100015747640528 | P36: https://blog.naver.com/indobangrang | T36: 9771187 | U36: 2882 | V36: 201700087 | W36: =CONCAT(CONCAT("https://assembly.go.kr/photo/", T36), ".jpg") -> https://assembly.go.kr/photo/9771187.jpg
A37: * | B37: 36 | C37: 문진석 | D37: 국회의원 | E37: 1 | F37: 경기 의정부 갑 | H37: 02-784-9030 | J37: jmoon123@naver.com | L37: 100024518042012 | P37: https://blog.naver.com/jmoon123 | T37: 9771204 | U37: 209 | V37: 201700035 | W37: =CONCAT(CONCAT("https://assembly.go.kr/photo/", T37), ".jpg") -> https://assembly.go.kr/photo/9771204.jpg
A38: * | B38: 37 | C38: 민병덕 | D38: 국회의원 | E38: =groups!$B$3 -> 1 | F38: 경기 안양 동안 갑 | L38: 100002917468835 | T38: 9771175 | U38: 110 | V38: 201700036 | W38: =CONCAT(CONCAT("https://assembly.go.kr/photo/", T38), ".jpg") -> https://assembly.go.kr/photo/9771175.jpg
A39: * | B39: 38 | C39: 민홍철 | D39: 국회의원 | E39: =groups!$B$3 -> 1 | F39: 경남 김해 갑 | H39: 02-784-6490 | I39: 055-312-4970 | K39: minstar21c | L39: 100002134022892 | M39: 2823min | O39: https://www.youtube.com/watch?v=WyFh94Kdcbo | P39: http://www.민사랑.com/ | T39: 9770764 | U39: 2615 | V39: 201700037 | W39: =CONCAT(CONCAT("https://assembly.go.kr/photo/", T39), ".jpg") -> https://assembly.go.kr/photo/9770764.jpg
A40: * | B40: 39 | C40: 김병주 | D40: 국회의원 | E40: =groups!$B$3 -> 1 | F40: 비례대표 | L40: 100047862105457 | T40: 9771268 | U40: 2917 | V40: 201700038 | W40: =CONCAT(CONCAT("https://assembly.go.kr/photo/", T40), ".jpg") -> https://assembly.go.kr/photo/9771268.jpg
A41: * | B41: 40 | C41: 박광온 | D41: 국회의원 | E41: =groups!$B$3 -> 1 | F41: 경기 수원 정 | H41: 02-784-5364 | J41: sotong533@gmail.com | K41: parkkwangon | L41: 100003365965286 | O41: https://www.youtube.com/channel/UCDmngSv6O5UzEgPpUrvcnjw | P41: http://blog.naver.com/kopark2012 | T41: 9770911 | U41: 2823 | V41: 201700039 | W41: =CONCAT(CONCAT("https://assembly.go.kr/photo/", T41), ".jpg") -> https://assembly.go.kr/photo/9770911.jpg
...

Sheet 20
B2: no | C2: name | D2: title | E2: group | F2: field | G2: mobile | H2: office_asm | I2: office_area | J2: email | K2: twitter | L2: facebook | M2: kakao | N2: instagram | O2: youtube | P2: web | Q2: blog | R2: cafe | S2: cyworld | T2: assembly | U2: assembly_no | V2: sponsor
B3: 1 | C3: 강병원 | D3: 국회의원 | E3: =groups!$B$3 -> 1 | F3: 서울 은평 을 | H3: 02-784-1422 | J3: kangbw89@gmail.com | K3: kbw89 | L3: 100001968500108 | O3: https://www.youtube.com/channel/UCRqhzBrMh6LIn9-LIbFLMEw | P3: http://blog.naver.com/kangbw89 | T3: 9770933 | U3: 2888 | V3: 201700001
B4: 2 | C4: 강창일 | D4: 국회의원 | E4: =groups!$B$3 -> 1 | F4: 제주 제주 갑 | H4: 02-784-6084 | I4: 064-745-9300 | J4: kang809@gmail.com | K4: kangci52 | L4: 100003224302073 | O4: https://www.youtube.com/channel/UC7bR36B2KDVvqUnl3TBNc_g | P4: http://www.kangci.net/memo.do | T4: 9770279 | U4: 155 | V4: 201700002
B5: 3 | C5: 강훈식 | D5: 국회의원 | E5: =groups!$B$3 -> 1 | F5: 충남 아산 을 | H5: 02-784-1045 | J5: gohoonsik@gmail.com | L5: 100008672748962 | O5: https://www.youtube.com/watch?v=DXKNIADDQ8E | P5: http://blog.naver.com/kanghunsik | T5: 9771007 | U5: 2853 | V5: 201700003
B6: 4 | C6: 고용진 | D6: 국회의원 | E6: =groups!$B$3 -> 1 | F6: 서울 노원 갑 | H6: 02-784-4840 | I6: 02-941-0413 | J6: gogoyongjin@naver.com | K6: yongjin_koh | L6: 100002728329388 | O6: https://www.youtube.com/watch?v=7qTR-KKkh4U | P6: http://blog.naver.com/kohyj64 | T6: 9770931 | U6: 2951 | V6: 201700004
B7: 5 | C7: 권미혁 | D7: 국회의원 | E7: =groups!$B$3 -> 1 | F7: 비례대표 | H7: 02-784-7727 | J7: kwonmh@na.go.kr | L7: 100011279868403 | O7: https://www.youtube.com/watch?v=g8DteK8z1yE | P7: http://www.kmh931.com | T7: 9771066 | U7: 2845 | V7: 201700005
B8: 6 | C8: 권칠승 | D8: 국회의원 | E8: =groups!$B$3 -> 1 | F8: 경기 화성 병 | H8: 02-784-1250 | I8: 031-222-0110 | K8: k7win_ | L8: 100011077455328 | O8: https://www.youtube.com/watch?v=Nz5cDRZ4EBA | P8: http://blog.naver.com/k7wins | T8: 9770998 | U8: 2841 | V8: 201700006
B9: 7 | C9: 금태섭 | D9: 국회의원 | E9: =groups!$B$3 -> 1 | F9: 서울 강서 갑 | H9: 02-784-9761~3 | I9: 02-2698-2256~7 | J9: gsgold2001@gmail.com | K9: gtaeboy | L9: 100001677850187 | O9: https://www.youtube.com/channel/UC2gl-I4_6wYTDLnrJtaiWAg | P9: http://www.gsgold.kr/ | T9: 9770937 | U9: 2849 | V9: 201700007
B10: 8 | C10: 기동민 | D10: 국회의원 | E10: =groups!$B$3 -> 1 | F10: 서울 성북 을 | H10: 02-784-3181 | L10: 100001422477735 | O10: https://www.youtube.com/watch?v=Cjm7G1RFCkI | P10: http://blog.naver.com/gidongmin | T10: 9770927 | U10: 2967 | V10: 201700008
B11: 10 | C11: 김경협 | D11: 국회의원 | E11: =groups!$B$3 -> 1 | F11: 경기 부천 원미 갑 | H11: 02-784-1190 | I11: 032-666-0520 | J11: ggh000@naver.com | K11: kimghkr | L11: 288294554590949 | O11: https://www.youtube.com/channel/UCcheolAyghSDXGsilCbg3WA | P11: http://www.kimgh.com | Q11: http://blog.naver.com/ggh000/ | T11: 9770712 | U11: 2606 | V11: 201700010
B12: 11 | C12: 김두관 | D12: 국회의원 | E12: =groups!$B$3 -> 1 | F12: 경기 김포 갑 | H12: 02-784-2566 | I12: 031-997-6840 | K12: dookwan | L12: 181899161847606 | O12: https://www.youtube.com/watch?v=a3SrEeUxPj0 | P12: http://okdk.kr/ | Q12: http://blog.naver.com/kikdok | T12: 9770997 | U12: 2836 | V12: 201700011
B13: 12 | C13: 김민기 | D13: 국회의원 | E13: =groups!$B$3 -> 1 | F13: 경기 용인 을 | H13: 02-784-1930 | I13: 031-282-9940 | J13: kimminki@assembly.go.kr | K13: kimminki84 | L13: 100001360593401 | O13: https://youtu.be/wI9fxU3_vPQ | P13: http://www.kimminki.co.kr/ | Q13: http://blog.naver.com/kminki84 | T13: 9770723 | U13: 2576 | V13: 201700012
B14: 13 | C14: 김병관 | D14: 국회의원 | E14: =groups!$B$3 -> 1 | F14: 경기 성남 분당 갑 | H14: 02-784-5490 | J14: kbgbundang@gmail.com | K14: bgkimjhs | L14: 100001222299868 | O14: https://www.youtube.com/watch?v=UUDajgv4F4g | P14: http://blog.naver.com/bgkim | T14: 9770983 | U14: 2858 | V14: 201700013
B15: 14 | C15: 김병기 | D15: 국회의원 | E15: =groups!$B$3 -> 1 | F15: 서울 동작 갑 | H15: 02-784-1322 | K15: thekimweapon | L15: 100011526436490 | O15: https://www.youtube.com/watch?v=Y6d4rRb7i4A | P15: http://kimbyungkee.kr/ | T15: 9770941 | U15: 2898 | V15: 201700014
B16: 15 | C16: 김병욱 | D16: 국회의원 | E16: =groups!$B$3 -> 1 | F16: 경기 성남 분당 을 | H16: 02-784-3670~2 | K16: 777byung1 | L16: 100001463493979 | O16: https://www.youtube.com/channel/UCkKmE-matF_3iwaw-Q7BjZA | P16: http://blog.naver.com/777byung | T16: 9770984 | U16: 2928 | V16: 201700015
B17: 16 | C17: 김부겸 | D17: 국회의원 | E17: =groups!$B$3 -> 1 | F17: 대구 수성 갑 | H17: 02-784-4367 | K17: hopekbk | L17: 100001886974215 | O17: https://www.youtube.com/watch?v=feoGpZZT0lE | Q17: http://blog.naver.com/kimbookyum | T17: 9770960 | U17: 305 | V17: 201700016
B18: 17 | C18: 김상희 | D18: 국회의원 | E18: =groups!$B$3 -> 1 | F18: 경기 부천 소사 | H18: 02-784-4173 | J18: shk@assembly.go.kr | K18: sosakim | L18: 100002181912858 | O18: https://www.youtube.com/watch?v=ibAHWTVvzl4 | P18: http://www.cleankim.kr/ | Q18: http://blog.naver.com/shk407 | T18: 9770527 | U18: 2760 | V18: 201700017
B19: 18 | C19: 김성수 | D19: 국회의원 | E19: =groups!$B$3 -> 1 | F19: 비례대표 | H19: 02-784-8780 | J19: kss_0909@naver.com | L19: 1935197206700792 | O19: https://www.youtube.com/watch?v=Hawue3lWJdo | P19: http://blog.naver.com/kss_0909 | T19: 9771065 | U19: 2871 | V19: 201700018
B20: 19 | C20: 김영주 | D20: 국회의원 | E20: =groups!$B$3 -> 1 | F20: 서울 영등포 갑 | H20: 02-784-2470 | I20: 02-2672-6712 | J20: joojoo2012@naver.com | K20: yjkim550727 | L20: 100001441525499 | O20: https://www.youtube.com/watch?v=aqfRVFnvWpo | P20: http://www.youngjoo.kr | T20: 9770975 | U20: 145 | V20: 201700019
B21: 20 | C21: 김영진 | D21: 국회의원 | E21: =groups!$B$3 -> 1 | F21: 경기 수원 병 | H21: 02-784-8410 | K21: minjoop | L21: 100001777896522 | M21: _anxcqd | O21: https://www.youtube.com/channel/UC6Bxiwajm3Fa4gdYTB2kB3g | P21: https://blog.naver.com/ersd34 | T21: 9770981 | U21: 2970 | V21: 201700020
B22: 21 | C22: 김영춘 | D22: 국회의원 | E22: =groups!$B$3 -> 1 | F22: 부산 부산진 갑 | H22: 02-784-1368 | J22: assemblyc@daum.net | K22: busanyc | L22: 179235295447468 | M22: _Uxlgkxl | O22: https://www.youtube.com/channel/UCcf-qCDE8787QUTV9hnZHFw | P22: http://blog.naver.com/busanyc | T22: 9770949 | U22: 222 | V22: 201700021
B23: 22 | C23: 김영호 | D23: 국회의원 | E23: =groups!$B$3 -> 1 | F23: 서울 서대문 을 | H23: 02-784-4020~2 | J23: kim-youngho@naver.com | K23: minjoo05 | L23: 100002182712870 | N23: minjoo_kimyoungho | O23: https://www.youtube.com/channel/UCQqH7k22MywV8dmbS5MJAAQ | P23: https://blog.naver.com/frencisco | T23: 9770934 | U23: 2863 | V23: 201700022
B24: 23 | C24: 김정우 | D24: 국회의원 | E24: =groups!$B$3 -> 1 | F24: 경기 군포 갑 | H24: 02-784-2417 | I24: 031-427-2311 | J24: withgunpo@gmail.com | K24: bravokorea00 | L24: 1020242416 | O24: https://www.youtube.com/watch?v=0qVnFg_LjsQ | P24: http://gunpokcw.blog.me/ | T24: 9770993 | U24: 2864 | V24: 201700023
B25: 24 | C25: 김종민 | D25: 국회의원 | E25: =groups!$B$3 -> 1 | F25: 충남 논산·계룡·금산 | H25: 02-784-5920 | K25: socmind | L25: 100001746723623 | O25: https://www.youtube.com/watch?v=MYS_8J8om5E | P25: https://blog.naver.com/socmind | T25: 9771009 | U25: 2833 | V25: 201700024
B26: 25 | C26: 김진표 | D26: 국회의원 | E26: =groups!$B$3 -> 1 | F26: 경기 수원 무 | H26: 02-784-3807 | K26: jinpyokim | L26: 100010889073617 | O26: https://www.youtube.com/user/jinpyotv | P26: http://blog.naver.com/jinpyo311 | T26: 9770982 | U26: 2775 | V26: 201700025
B27: 26 | C27: 김철민 | D27: 국회의원 | E27: =groups!$B$3 -> 1 | F27: 경기 안산 상록 을 | H27: 02-784-2135 | I27: 031-405-7755 | J27: kcm8764@naver.com | K27: kimcm8764 | L27: 727022040682171 | O27: https://www.youtube.com/watch?v=D9kQAUbKZ4c | P27: http://blog.naver.com/kcm8764 | T27: 9770986 | U27: 2966 | V27: 201700026
B28: 27 | C28: 김태년 | D28: 국회의원 | E28: =groups!$B$3 -> 1 | F28: 경기 성남 수정 | H28: 02-784-4570 | I28: 031-751-4048 | J28: ktn0320@daum.net | K28: kimtaenyeon | L28: 100002122729408 | O28: https://www.youtube.com/watch?v=NwalcMu_Bi0 | P28: http://www.ktn21.com/ | Q28: http://blog.naver.com/ktn208 | T28: 9770741 | U28: 556 | V28: 201700027
B29: 28 | C29: 김한정 | D29: 국회의원 | E29: =groups!$B$3 -> 1 | F29: 경기 남양주 을 | H29: 02-784-0496 | I29: 031-573-6669 | K29: hanjungok | L29: 100000513084408 | O29: https://www.youtube.com/watch?v=aHysDIgrSVY | P29: http://blog.naver.com/hanjungkim | T29: 9770991 | U29: 2931 | V29: 201700028
B30: 29 | C30: 김해영 | D30: 국회의원 | E30: =groups!$B$3 -> 1 | F30: 부산 연제 | H30: 02-784-1051~3 | J30: hykim0417@naver.com | L30: 100001994440268 | O30: https://www.youtube.com/watch?v=T9LnLb3XHnU | P30: http://blog.naver.com/hykim0417 | T30: 9770953 | U30: 2924 | V30: 201700029
B31: 30 | C31: 김현권 | D31: 국회의원 | E31: =groups!$B$3 -> 1 | F31: 비례대표 | H31: 02-784-2841 | J31: farmhk20@gmail.com | K31: hanwooabi | L31: 100000819139297 | O31: https://www.youtube.com/channel/UCdrkeofzprOvPjF4FVPzc4g | P31: http://blog.naver.com/farmhk20 | T31: 9771061 | U31: 2875 | V31: 201700030
B32: 31 | C32: 김현미 | D32: 국회의원 | E32: =groups!$B$3 -> 1 | F32: 경기 고양 정 | H32: 02-784-4990 | I32: 031-925-2024 | J32: 7844990@naver.com | K32: hyunmeek | L32: 100001518504936 | O32: https://youtu.be/I41DcWJVngc | P32: http://hyunmee.net | T32: 9770746 | U32: 128 | V32: 201700031
B33: 32 | C33: 남인순 | D33: 국회의원 | E33: =groups!$B$3 -> 1 | F33: 서울 송파 병 | H33: 02-784-5980 | J33: nisoon@na.go.kr | K33: nisoon | L33: 100000654518088 | M33: _ewwiM | N33: flynisoon | O33: https://www.youtube.com/watch?v=Ekhq13BipHk | P33: http://www.nisoon.co.kr/ | Q33: http://blog.naver.com/nisoon | T33: 9770752 | U33: 2618 | V33: 201700032
B34: 33 | C34: 노웅래 | D34: 국회의원 | E34: =groups!$B$3 -> 1 | F34: 서울 마포 갑 | H34: 02-788-2203 | I34: 02-3275-1664 | J34: wraenoh@hanmail.net | K34: gowith_wraenoh | L34: 100011462499036 | O34: https://www.youtube.com/watch?v=iVrlv5HADq8 | P34: http://blog.naver.com/with_wraenoh | T34: 9770753 | U34: 133 | V34: 201700033
B35: 34 | C35: 도종환 | D35: 국회의원 | E35: =groups!$B$3 -> 1 | F35: 충북 청주 흥덕 | H35: 02-784-2537 | I35: 043-235-0300 | J35: djhpoem@assembly.go.kr | K35: djhpoem2 | L35: 100004000310066 | O35: https://www.youtube.com/watch?v=v8FS5f0dgmg | P35: http://djh333.co.kr/ | T35: 9770755 | U35: 2585 | V35: 201700034
B36: 35 | C36: 이수혁 | D36: 국회의원 | E36: =groups!$B$3 -> 1 | F36: 비례대표 | H36: 02-784-9671 | L36: 100011414262783 | O36: https://www.youtube.com/watch?v=-V5wvpzSIHE | P36: http://blog.naver.com/shlee197520 | T36: 9771088 | U36: 2882 | V36: 201700087
B37: 36 | C37: 문희상 | D37: 국회의원 | E37: 8 | F37: 경기 의정부 갑 | H37: 02-784-1261 | I37: 031-877-3333 | J37: moonhs@assembly.go.kr | K37: moonhstw | L37: 100003028875854 | O37: https://www.youtube.com/watch?v=jnrp-sDYEZ8 | P37: http://www.moonhs.net/ | Q37: https://blog.naver.com/moonhs1001 | T37: 9770084 | U37: 209 | V37: 201700035
B38: 37 | C38: 민병두 | D38: 국회의원 | E38: =groups!$B$3 -> 1 | F38: 서울 동대문 을 | H38: 02-788-2256 | J38: bdmin1958@assembly.go.kr | K38: bdmin1958 | L38: 100001959429059 | O38: https://www.youtube.com/watch?v=oA-f48pyY4k | P38: http://www.bdmin.net/ | T38: 9770761 | U38: 110 | V38: 201700036
B39: 38 | C39: 민홍철 | D39: 국회의원 | E39: =groups!$B$3 -> 1 | F39: 경남 김해 갑 | H39: 02-784-6490 | I39: 055-312-4970 | K39: minstar21c | L39: 100002134022892 | M39: 2823min | O39: https://www.youtube.com/watch?v=WyFh94Kdcbo | P39: http://www.민사랑.com/ | T39: 9770764 | U39: 2615 | V39: 201700037
B40: 39 | C40: 박경미 | D40: 국회의원 | E40: =groups!$B$3 -> 1 | F40: 비례대표 | H40: 02-784-6120 | J40: parkkm321@naver.com | L40: 100000956145907 | M40: _PPiGxl | O40: https://www.youtube.com/channel/UCk4gACsvSKF9_A4-ZjRC6og | P40: http://blog.naver.com/parkkm321 | T40: 9771056 | U40: 2917 | V40: 201700038
B41: 40 | C41: 박광온 | D41: 국회의원 | E41: =groups!$B$3 -> 1 | F41: 경기 수원 정 | H41: 02-784-5364 | J41: sotong533@gmail.com | K41: parkkwangon | L41: 100003365965286 | O41: https://www.youtube.com/channel/UCDmngSv6O5UzEgPpUrvcnjw | P41: http://blog.naver.com/kopark2012 | T41: 9770911 | U41: 2823 | V41: 201700039
...

Sheet events
B2: no | C2: name | D2: sheet | E2: detail
B3: 1 | C3: 상임위원회 | D3: normalgroups

Sheet modifiedlaws
B2: no | C2: title | D2: memberid | E2: member_sheet | F2: opinion | G2: detail | H2: web

Sheet speciallaws
B2: no | C2: title | D2: memberid | E2: member_sheet | F2: opinion | G2: detail | H2: web

Sheet normalgroups
B2: no | C2: title | D2: memberid | E2: member_sheet | F2: opinion | G2: detail | H2: web | I2: name
B3: 1 | C3: 교육위원회 | D3: 5 | E3: congressman | H3: https://edu.na.go.kr:444/edu/index.do | I3: 강득구
B4: 1 | D4: 18 | I4: 권인숙
B5: 1 | D5: 26 | I5: 김철민
B6: 1 | D6: 50 | I6: 박찬대
B7: 1 | D7: 86 | I7: 서동용
B8: 1 | D8: 114 | I8: 최인호
B9: 1 | D9: 302 | I9: 윤영덕
B10: 1 | D10: 328 | I10: 이탄희
B11: 1 | D11: 338 | I11: 정청래
B12: 1 | D12: 127 | I12: 곽상도
B13: 1 | D13: 132 | I13: 김병욱
B14: 1 | D14: 155 | I14: 배준영
B15: 1 | D15: 196 | I15: 정경희
... B18: 1 | D18: 233 | I18: 강민정
B19: 2 | C19: 보건복지위원회 | D19: 1 | E19: congressman | H19: https://health.na.go.kr:444/health/index.do | I19: 강병원
B20: 2 | D20: 6 | I20: 권칠승
B21: 2 | D21: 2 | I21: 강선우
B22: 2 | D22: 16 | I22: 고영인
B23: 2 | D23: 32 | I23: 남인순
B24: 2 | D24: 44 | I24: 김성주
B25: 2 | D25: 62 | I25: 김원이
B26: 2 | D26: 87 | I26: 서영석
B27: 2 | D27: 96 | I27: 신현영
B28: 2 | D28: 97 | I28: 인재근
B29: 2 | D29: 98 | I29: 임종성
B30: 2 | D30: 106 | I30: 정춘숙
B31: 2 | D31: 117 | I31: 한정애
... B43: 2 | D43: 356 | I43: 강기윤
B44: 3 | C44: 산업통상자원중소벤처기업위원회 | D44: 3 | E44: congressman | H44: https://industry.na.go.kr:444/industry/index.do | I44: 강훈식
B45: 3 | D45: 13 | I45: 고민정
B46: 3 | D46: 300 | I46: 김성환
B47: 3 | D47: 304 | I47: 송갑석
B48: 3 | D48: 93 | I48: 신영대
B49: 3 | D49: 94 | I49: 이학영
B50: 3 | D50: 95 | I50: 신정훈
B51: 3 | D51: 313 | I51: 이규민
B52: 3 | D52: 315 | I52: 이동주
B53: 3 | D53: 318 | I53: 이성만
B54: 3 | D54: 319 | I54: 이소영
...

Sheet specialgroups
B2: no | C2: title | D2: memberid | E2: member_sheet | F2: opinion | G2: detail | H2: web
B3: 102 | C3: 헌법개정 특별위원회 | D3: ='20'!B4 -> 2 | E3: congressman
B4: 102 | D4: ='20'!B7 -> 5 | E4: congressman
B5: 102 | D5: ='20'!B11 -> 10 | E5: congressman
B6: 102 | D6: ='20'!B25 -> 24 | E6: congressman
B7: 102 | D7: ='20'!B43 -> 43 | E7: congressman
B8: 102 | D8: ='20'!B52 -> 52 | E8: congressman
B9: 102 | D9: ='20'!B54 -> 54 | E9: congressman
B10: 102 | D10: ='20'!B84 -> 85 | E10: congressman
B11: 102 | D11: ='20'!B88 -> 89 | E11: congressman
B12: 102 | D12: ='20'!B89 -> 90 | E12: congressman
B13: 102 | D13: ='20'!B90 -> 91 | E13: congressman
B14: 102 | D14: ='20'!B99 -> 100 | E14: congressman
B15: 102 | D15: ='20'!B100 -> 101 | E15: congressman
B16: 102 | D16: ='20'!B110 -> 111 | E16: congressman
B17: 102 | D17: ='20'!B113 -> 114 | E17: congressman
B18: 102 | D18: ='20'!B123 -> 124 | E18: congressman
B19: 102 | D19: ='20'!B139 -> 141 | E19: congressman
B20: 102 | D20: ='20'!B145 -> 147 | E20: congressman
B21: 102 | D21: ='20'!B166 -> 168 | E21: congressman
B22: 102 | D22: ='20'!B183 -> 185 | E22: congressman
B23: 102 | D23: ='20'!B193 -> 198 | E23: congressman
B24: 102 | D24: ='20'!B194 -> 199 | E24: congressman
B25: 102 | D25: ='20'!B196 -> 201 | E25: congressman
B26: 102 | D26: ='20'!#REF! -> #ERROR! | E26: congressman
B27: 102 | D27: ='20'!B205 -> 211 | E27: congressman
B28: 102 | D28: ='20'!B214 -> 221 | E28: congressman
B29: 102 | D29: ='20'!B221 -> 228 | E29: congressman
B30: 102 | D30: ='20'!B224 -> 231 | E30: congressman
B31: 102 | D31: ='20'!#REF! -> #ERROR! | E31: congressman
B32: 102 | D32: ='20'!B242 -> 251 | E32: congressman
B33: 102 | D33: ='20'!B255 -> 264 | E33: congressman
B34: 102 | D34: ='20'!B268 -> 278 | E34: congressman
B35: 102 | D35: ='20'!B276 -> 286 | E35: congressman
B36: 102 | D36: ='20'!#REF! -> #ERROR! | E36: congressman
B37: 103 | C37: 미래창조과학방송통신위원회 | D37: ='20'!B6 -> 4 | E37: congressman
B38: 103 | D38: ='20'!B19 -> 18 | E38: congressman
B39: 103 | D39: ='20'!B32 -> 31 | E39: congressman
B40: 103 | D40: ='20'!B51 -> 51 | E40: congressman
B41: 103 | D41: ='20'!B54 -> 54 | E41: congressman
...

Sheet groups
B2: no | C2: title | D2: detail | E2: office | F2: email | G2: twitter | H2: facebook | I2: kakao | J2: instagram | K2: youtube | L2: web | M2: blog | N2: café | O2: cyworld | P2: sponsor
B3: 1 | C3: 더불어민주당 | E3: 1577-7667 | G3: TheMinjoo_Kr | H3: 163693313660505 | J3: theminjoo | K3: https://www.youtube.com/user/minjootv | L3: http://theminjoo.kr | M3: http://blog.naver.com/yesminjoo | P3: 1001
B4: 2 | C4: 미래통합당 | E4: 02-3786-3000 | G4: liberty_kr | H4: 295775117138819 | I4: libertykorea | J4: libertykorea | K4: https://www.youtube.com/c/%EC%9E%90%EC%9C%A0%ED%95%9C%EA%B5%AD%EB%8B%B9 | L4: http://www.libertykoreaparty.kr | M4: http://blog.libertykoreaparty.kr/ | P4: 1002
B5: 3 | C5: 정의당 | E5: 02-2038-0103 | G5: kr_justice | H5: 512722405481009 | I5: jbhyendx | J5: justice_party | K5: https://www.youtube.com/channel/UC4KdOy46f0HCJBqTiq7MLPg | L5: http://www.justice21.org | M5: http://blog.naver.com/justiceparty | P5: 1003
B6: 4 | C6: 국민의당 | E6: 02-2070-5600 | G6: bareunmiraedang | H6: 1651975401769490 | J6: peopleparty21 | K6: https://www.youtube.com/channel/UCpnetwDnXC5eFlQhjmbv12g | L6: http://bareunmirae.kr/ | P6: 1004
B7: 5 | C7: 열린민주당 | H7: 1869948593320390 | J7: gkpp0815 | K7: https://www.youtube.com/channel/UC5Ys11G8I-ULCXm6cNowB1w | L7: http://kpparty.kr/ | N7: https://m.cafe.naver.com/kppmembers.cafe | P7: 1005
B8: 6 | C8: 기본소득당 | E8: 02-6933-0012 | F8: theminjungparty@gmail.com | H8: 1643827669215080 | I8: _nldxexl | J8: minjungparty | K8: https://www.youtube.com/channel/UCD2FurCIhOsG3FsTM1-jirA | L8: http://minjungparty.com/main/ | P8: 1006
B9: 7 | C9: 시대전환 | E9: 070-7623-0415 | H9: 102260751224365 | J9: transition_kr | K9: https://www.youtube.com/channel/UCUu0c6atSniR5aPW9pNPiVA/featured | P9: 1007
B10: 8 | C10: 무소속 | P10: 9001
