Workbook

Sheet info
B2: version | C2: 1.1.8
B3: notice | C3: 이제는 직접민주주의로 참여하는 시대입니다. 다양한 방법으로 지역구 의원이 무슨일을 하는지 확인하고 잘하면 칭찬하고 못하면 비판하며 때로는 토론도 해보세요.
B4: notice_date | C4: 43310
B5: patch | C5: 관심의원 법안 대표발의 알림 기능 추가 [1.1.7.1] 6.13 지방선거 국회의원 사퇴 및 당선자 적용 [1.1.7] 1. 권석창 의원직 상실 적용 2. 비정상 종료 관련 수정 [1.1.6.1] 1. 박지원, 정세균 의원 소속 정정 [1.1.6] 1. 국민의당, 바른정당 합당 적용 2. 바른정당 탈당 적용 3. 의원직 상실 적용 [1.1.5] 1. 바른정당 2차 탈당 적용 2. 의원직 상실, 사퇴 적용 [1.1.4] 1. 앱스토어 검색어 추가 2. SDK 업데이트 [1.1.3.1] 1. 바른정당 탈당 의원 소속 정당 변경 2. 민중당, 대한애국당 정보 업데이트 [1.1.3] 1. iOS 11에서 검색창 없어지는 문제 수정 [1.1.2.1] 1. 정치후원 기능 추가 - 소액결제를 통한 정치후원 기능 : 계약된 국회의원에 한함 2. 정치후원 탭 추가 3. 정치후원 버튼(￦) 추가 [1.1.1] 1. 의원정보 일부 업데이트 2. 상임위원회 정보 업데이트 3. 정당정보 및 의원소속 업데이트 4. 정당정보 표시 관련 버그 수정 5. 배너광고 제거, 전면 광고로 대체 6. 광고 SDK 업데이트 [1.1.0] 1. 웹페이지를 Safari대신 앱안에서 띄우도록 수정

Sheet congressman
B2: no | C2: name | D2: title | E2: group | F2: field | G2: mobile | H2: office_asm | I2: office_area | J2: email | K2: twitter | L2: facebook | M2: kakao | N2: instagram | O2: youtube | P2: web | Q2: blog | R2: café | S2: cyworld | T2: assembly | U2: assembly_no | V2: sponsor
B3: 1 | C3: 강병원 | D3: 국회의원 | E3: =groups!$B$3 -> 1 | F3: 서울 은평 을 | H3: 02-784-1422 | J3: kangbw89@gmail.com | K3: kbw89 | L3: 100001968500108 | O3: https://www.youtube.com/channel/UCRqhzBrMh6LIn9-LIbFLMEw | P3: http://blog.naver.com/kangbw89 | T3: 9770933 | U3: 2888 | V3: 201700001
B4: 2 | C4: 강창일 | D4: 국회의원 | E4: =groups!$B$3 -> 1 | F4: 제주 제주 갑 | H4: 02-784-6084 | I4: 064-745-9300 | J4: kang809@gmail.com | K4: kangci52 | L4: 100003224302073 | O4: https://www.youtube.com/channel/UC7bR36B2KDVvqUnl3TBNc_g | P4: http://www.kangci.net/ | T4: 9770279 | U4: 155 | V4: 201700002
B5: 3 | C5: 강훈식 | D5: 국회의원 | E5: =groups!$B$3 -> 1 | F5: 충남 아산 을 | H5: 02-784-1045 | J5: gohoonsik@gmail.com | L5: 435445243514911 | O5: https://youtu.be/VJfs2uUgF5Y | P5: http://blog.naver.com/kanghunsik | T5: 9771007 | U5: 2853 | V5: 201700003
B6: 4 | C6: 고용진 | D6: 국회의원 | E6: =groups!$B$3 -> 1 | F6: 서울 노원 갑 | H6: 02-784-4840 | I6: 02-941-0413 | J6: gogoyongjin@naver.com | K6: yongjin_koh | L6: 100002728329388 | O6: https://www.youtube.com/watch?v=7qTR-KKkh4U | P6: http://blog.naver.com/kohyj64 | T6: 9770931 | U6: 2951 | V6: 201700004
B7: 5 | C7: 권미혁 | D7: 국회의원 | E7: =groups!$B$3 -> 1 | F7: 비례대표 | H7: 02-784-7727 | J7: kwonmh@na.go.kr | O7: https://www.youtube.com/watch?v=ctfXE8OsaXw | P7: http://www.kmh931.com | T7: 9771066 | U7: 2845 | V7: 201700005
B8: 6 | C8: 권칠승 | D8: 국회의원 | E8: =groups!$B$3 -> 1 | F8: 경기 화성 병 | H8: 02-784-1250 | I8: 031-222-0110 | K8: k7win_ | L8: 100011077455328 | O8: https://www.youtube.com/watch?v=nAEco9WX5Jo | P8: http://blog.naver.com/k7wins | T8: 9770998 | U8: 2841 | V8: 201700006
B9: 7 | C9: 금태섭 | D9: 국회의원 | E9: =groups!$B$3 -> 1 | F9: 서울 강서 갑 | H9: 02-784-9761~3 | I9: 02-2698-2256~7 | J9: gsgold2001@gmail.com | K9: gtaeboy | L9: 100001677850187 | O9: https://www.youtube.com/watch?v=wnFHSoCh3UY | P9: http://www.gsgold.kr/ | T9: 9770937 | U9: 2849 | V9: 201700007
B10: 8 | C10: 기동민 | D10: 국회의원 | E10: =groups!$B$3 -> 1 | F10: 서울 성북 을 | H10: 02-784-3181 | L10: 100001422477735 | O10: https://www.youtube.com/watch?v=Cjm7G1RFCkI | P10: http://blog.naver.com/gidongmin | T10: 9770927 | U10: 2967 | V10: 201700008
B11: 10 | C11: 김경협 | D11: 국회의원 | E11: =groups!$B$3 -> 1 | F11: 경기 부천 원미 갑 | H11: 02-784-1190 | I11: 032-666-0520 | J11: ggh000@naver.com | K11: kimghkr | L11: 100000942849824 | O11: https://www.youtube.com/watch?v=LWJdOSX295k | P11: http://www.kimgh.com | Q11: http://blog.naver.com/ggh000/ | T11: 9770712 | U11: 2606 | V11: 201700010
B12: 11 | C12: 김두관 | D12: 국회의원 | E12: =groups!$B$3 -> 1 | F12: 경기 김포 갑 | H12: 02-784-2566 | I12: 031-997-6840 | K12: dookwan | L12: 181899161847606 | O12: https://www.youtube.com/watch?v=r6nbce6XUGc | P12: http://okdk.kr/ | Q12: http://blog.naver.com/kikdok | T12: 9770997 | U12: 2836 | V12: 201700011
B13: 12 | C13: 김민기 | D13: 국회의원 | E13: =groups!$B$3 -> 1 | F13: 경기 용인 을 | H13: 02-784-1930 | I13: 031-282-9940 | J13: kimminki@assembly.go.kr | K13: kimminki84 | L13: 100001360593401 | O13: https://youtu.be/A-shtA2PED4 | P13: http://www.kimminki.co.kr/ | Q13: http://blog.naver.com/kminki84 | T13: 9770723 | U13: 2576 | V13: 201700012
B14: 13 | C14: 김병관 | D14: 국회의원 | E14: =groups!$B$3 -> 1 | F14: 경기 성남 분당 갑 | H14: 02-784-5490 | J14: kbgbundang@gmail.com | K14: bgkimjhs | L14: 100001222299868 | O14: https://www.youtube.com/watch?v=4pzalXGSj94 | P14: http://blog.naver.com/bgkim | T14: 9770983 | U14: 2858 | V14: 201700013
B15: 14 | C15: 김병기 | D15: 국회의원 | E15: =groups!$B$3 -> 1 | F15: 서울 동작 갑 | H15: 02-784-1322 | K15: thekimweapon | L15: 100011526436490 | O15: https://www.youtube.com/watch?v=yJ0qo3hmgco | P15: http://kimbyungkee.kr/ | T15: 9770941 | U15: 2898 | V15: 201700014
B16: 15 | C16: 김병욱 | D16: 국회의원 | E16: =groups!$B$3 -> 1 | F16: 경기 성남 분당 을 | H16: 02-784-3670~2 | K16: 777byung1 | L16: 100001463493979 | O16: https://www.youtube.com/channel/UCkKmE-matF_3iwaw-Q7BjZA | P16: http://blog.naver.com/777byung | T16: 9770984 | U16: 2928 | V16: 201700015
B17: 16 | C17: 김부겸 | D17: 국회의원 | E17: =groups!$B$3 -> 1 | F17: 대구 수성 갑 | H17: 02-784-4367 | K17: hopekbk | O17: https://www.youtube.com/watch?v=fSXFigCd3Kw | P17: http://www.hopekbk.or.kr/xe/ | T17: 9770960 | U17: 305 | V17: 201700016
B18: 17 | C18: 김상희 | D18: 국회의원 | E18: =groups!$B$3 -> 1 | F18: 경기 부천 소사 | H18: 02-784-4173 | J18: shk@assembly.go.kr | K18: SosaKim | L18: 100002181912858 | O18: https://www.youtube.com/watch?v=ibAHWTVvzl4 | P18: http://www.cleankim.kr/ | Q18: http://blog.naver.com/shk407 | T18: 9770527 | U18: 2760 | V18: 201700017
B19: 18 | C19: 김성수 | D19: 국회의원 | E19: =groups!$B$3 -> 1 | F19: 비례대표 | H19: 02-784-8780 | J19: kss_0909@naver.com | O19: https://www.youtube.com/watch?v=ZExMzWHZDyo | P19: http://blog.naver.com/kss_0909 | T19: 9771065 | U19: 2871 | V19: 201700018
B20: 19 | C20: 김영주 | D20: 국회의원 | E20: =groups!$B$3 -> 1 | F20: 서울 영등포 갑 | H20: 02-784-2470 | I20: 02-2672-6712 | J20: joojoo2012@naver.com | K20: yjkim550727 | L20: 100001441525499 | O20: https://www.youtube.com/watch?v=aqfRVFnvWpo | P20: http://www.youngjoo.kr | T20: 9770975 | U20: 145 | V20: 201700019
B21: 20 | C21: 김영진 | D21: 국회의원 | E21: =groups!$B$3 -> 1 | F21: 경기 수원 병 | H21: 02-784-8410 | K21: minjoop | L21: 100001777896522 | O21: https://www.youtube.com/watch?v=uLnQf9iBMT4 | P21: http://www.assembly.go.kr/assm/memPop/memPopup.do?dept_cd=9770981 | T21: 9770981 | U21: 2970 | V21: 201700020
B22: 21 | C22: 김영춘 | D22: 국회의원 | E22: =groups!$B$3 -> 1 | F22: 부산 부산진 갑 | H22: 02-784-1368 | J22: assemblyc@daum.net | K22: busanyc | L22: 100000714187534 | O22: https://www.youtube.com/watch?v=X6dvME5y2hA | P22: http://blog.naver.com/busanyc | T22: 9770949 | U22: 222 | V22: 201700021
B23: 22 | C23: 김영호 | D23: 국회의원 | E23: =groups!$B$3 -> 1 | F23: 서울 서대문 을 | H23: 02-784-4020~2 | J23: kim-youngho@naver.com | K23: minjoo05 | L23: 100002182712870 | O23: https://youtu.be/zLp9Yq_XVoQ | P23: http://www.minjoo05.com/ | T23: 9770934 | U23: 2863 | V23: 201700022
B24: 23 | C24: 김정우 | D24: 국회의원 | E24: =groups!$B$3 -> 1 | F24: 경기 군포 갑 | H24: 02-784-2417 | I24: 031-427-2311 | J24: withgunpo@gmail.com | K24: bravokorea00 | L24: 1020242416 | O24: https://www.youtube.com/watch?v=GJ3AfyBKmYI | P24: http://gunpokcw.blog.me/ | T24: 9770993 | U24: 2864 | V24: 201700023
B25: 24 | C25: 김종민 | D25: 국회의원 | E25: =groups!$B$3 -> 1 | F25: 충남 논산·계룡·금산 | H25: 02-784-5920 | K25: socmind | L25: 100001746723623 | O25: https://www.youtube.com/watch?v=MYS_8J8om5E | P25: http://www.assembly.go.kr/assm/memPop/memPopup.do?dept_cd=9771009 | T25: 9771009 | U25: 2833 | V25: 201700024
B26: 25 | C26: 김진표 | D26: 국회의원 | E26: =groups!$B$3 -> 1 | F26: 경기 수원 무 | H26: 02-784-3807 | K26: jinpyokim | L26: 708378359214924 | O26: https://www.youtube.com/watch?v=WawAUIoT0PU | P26: http://blog.naver.com/jinpyo311 | T26: 9770982 | U26: 2775 | V26: 201700025
B27: 26 | C27: 김철민 | D27: 국회의원 | E27: =groups!$B$3 -> 1 | F27: 경기 안산 상록 을 | H27: 02-784-2135 | I27: 031-405-7755 | J27: kcm8764@naver.com | K27: kimcm8764 | L27: 727022040682171 | O27: https://www.youtube.com/watch?v=z4S7TGxVGto | P27: http://blog.naver.com/kcm8764 | T27: 9770986 | U27: 2966 | V27: 201700026
B28: 27 | C28: 김태년 | D28: 국회의원 | E28: =groups!$B$3 -> 1 | F28: 경기 성남 수정 | H28: 02-784-4570 | I28: 031-751-4048 | J28: ktn0320@daum.net | K28: kimtaenyeon | L28: 100002122729408 | O28: https://www.youtube.com/watch?v=0vLxmt7lFLU | P28: http://www.ktn21.com/ | Q28: http://blog.naver.com/ktn208 | T28: 9770741 | U28: 556 | V28: 201700027
B29: 28 | C29: 김한정 | D29: 국회의원 | E29: =groups!$B$3 -> 1 | F29: 경기 남양주 을 | H29: 02-784-0496 | I29: 031-573-6669 | K29: hanjungok | L29: 1498882637005625 | O29: https://www.youtube.com/watch?v=aHysDIgrSVY | P29: http://blog.naver.com/hanjungkim | T29: 9770991 | U29: 2931 | V29: 201700028
B30: 29 | C30: 김해영 | D30: 국회의원 | E30: =groups!$B$3 -> 1 | F30: 부산 연제 | H30: 02-784-1051~3 | J30: hykim0417@naver.com | K30: hykim0417 | L30: 100001994440268 | O30: https://www.youtube.com/watch?v=zJj8IsNsk0o | P30: http://blog.naver.com/hykim0417 | T30: 9770953 | U30: 2924 | V30: 201700029
B31: 30 | C31: 김현권 | D31: 국회의원 | E31: =groups!$B$3 -> 1 | F31: 비례대표 | H31: 02-784-2841 | J31: farmhk20@gmail.com | K31: hanwooabi | L31: 100000819139297 | O31: https://www.youtube.com/watch?v=bXJqcrvXigg | P31: http://blog.naver.com/farmhk20 | T31: 9771061 | U31: 2875 | V31: 201700030
B32: 31 | C32: 김현미 | D32: 국회의원 | E32: =groups!$B$3 -> 1 | F32: 경기 고양 정 | H32: 02-784-4990 | I32: 031-925-2024 | J32: 7844990@naver.com | L32: 100001518504936 | O32: https://www.youtube.com/watch?v=8c2cNThdyzk | P32: http://hyunmee.net | T32: 9770746 | U32: 128 | V32: 201700031
B33: 32 | C33: 남인순 | D33: 국회의원 | E33: =groups!$B$3 -> 1 | F33: 서울 송파 병 | H33: 02-784-5980 | J33: nisoon@na.go.kr | K33: nisoon | L33: 100000654518088 | O33: https://www.youtube.com/watch?v=Ekhq13BipHk | P33: http://www.nisoon.co.kr/ | Q33: http://blog.naver.com/nisoon | T33: 9770752 | U33: 2618 | V33: 201700032
B34: 33 | C34: 노웅래 | D34: 국회의원 | E34: =groups!$B$3 -> 1 | F34: 서울 마포 갑 | H34: 02-788-2203 | I34: 02-3275-1664 | J34: wraenoh@hanmail.net | K34: gowith_wraenoh | L34: 100011462499036 | O34: https://www.youtube.com/watch?v=75m-SRfLh8M | P34: http://blog.naver.com/with_wraenoh | T34: 9770753 | U34: 133 | V34: 201700033
B35: 34 | C35: 도종환 | D35: 국회의원 | E35: =groups!$B$3 -> 1 | F35: 충북 청주 흥덕 | H35: 02-784-2537 | I35: 043-235-0300 | J35: djhpoem@assembly.go.kr | K35: djhpoem2 | L35: 100004000310066 | O35: https://www.youtube.com/watch?v=2sfe-BZRLBw | P35: http://djhpoem.co.kr/ | T35: 9770755 | U35: 2585 | V35: 201700034
B36: 35 | C36: 이수혁 | D36: 국회의원 | E36: =groups!$B$3 -> 1 | F36: 비례대표 | H36: 02-784-9671 | L36: 100011414262783 | O36: https://www.youtube.com/watch?v=K4sVVZxfG74 | P36: http://blog.naver.com/shlee197520 | T36: 9771088 | U36: 2882 | V36: 201700087
B37: 36 | C37: 문희상 | D37: 국회의원 | E37: =groups!$B$3 -> 1 | F37: 경기 의정부 갑 | H37: 02-784-1261 | I37: 031-877-3333 | J37: moonhs@assembly.go.kr | K37: moonhstw | L37: 100003028875854 | O37: https://www.youtube.com/watch?v=WOGAH14XaFc | P37: http://www.moonhs.net/ | T37: 9770084 | U37: 209 | V37: 201700035
B38: 37 | C38: 민병두 | D38: 국회의원 | E38: =groups!$B$3 -> 1 | F38: 서울 동대문 을 | H38: 02-788-2256 | J38: bdmin1958@assembly.go.kr | K38: bdmin1958 | L38: 100001959429059 | O38: https://www.youtube.com/watch?v=Y5Ly202f9P0 | P38: http://www.bdmin.net/ | T38: 9770761 | U38: 110 | V38: 201700036
B39: 38 | C39: 민홍철 | D39: 국회의원 | E39: =groups!$B$3 -> 1 | F39: 경남 김해 갑 | H39: 02-784-6490 | I39: 055-312-4970 | K39: minstar21c | L39: 100002134022892 | O39: https://www.youtube.com/watch?v=WyFh94Kdcbo | P39: http://www.민사랑.com/ | T39: 9770764 | U39: 2615 | V39: 201700037
B40: 39 | C40: 박경미 | D40: 국회의원 | E40: =groups!$B$3 -> 1 | F40: 비례대표 | H40: 02-784-6120 | J40: parkkm321@naver.com | L40: 100000956145907 | O40: https://www.youtube.com/watch?v=dWKcdeOTrZA | P40: http://blog.naver.com/parkkm321 | T40: 9771056 | U40: 2917 | V40: 201700038
B41: 40 | C41: 박광온 | D41: 국회의원 | E41: =groups!$B$3 -> 1 | F41: 경기 수원 정 | H41: 02-784-5364 | J41: sotong533@gmail.com | K41: parkkwangon | L41: 1554426271445959 | O41: https://www.youtube.com/watch?v=CHngLAqhhdA | P41: http://blog.naver.com/kopark2012 | T41: 9770911 | U41: 2823 | V41: 201700039
...

Sheet events
B2: no | C2: name | D2: sheet | E2: detail
B3: 1 | C3: 상임위원회 | D3: normalgroups
B4: 2 | C4: 특별위원회 | D4: specialgroups
B5: 3 | C5: 특별법안 | D5: speciallaws
B6: 4 | C6: 개정법률안 | D6: modifiedlaws

Sheet modifiedlaws
B2: no | C2: title | D2: memberid | E2: member_sheet | F2: opinion | G2: detail | H2: web
B3: 400 | C3: 소득세법 개정안 발의(종교인 과세 2년 유예) | D3: =congressman!B26 -> 25 | E3: congressman | H3: http://likms.assembly.go.kr/bill/billDetail.do?billId=PRC_A1X7Z0Z8V0D9L1K1R0T0Z2S7A1H3C5
B4: 400 | D4: =congressman!#REF! -> #REF! | E4: congressman
B5: 400 | D5: =congressman!B127 -> 129 | E5: congressman
B6: 400 | D6: =congressman!B135 -> 137 | E6: congressman
B7: 400 | D7: =congressman!B136 -> 138 | E7: congressman
B8: 400 | D8: =congressman!B137 -> 139 | E8: congressman
B9: 400 | D9: =congressman!B21 -> 20 | E9: congressman
B10: 400 | D10: =congressman!B27 -> 26 | E10: congressman
B11: 400 | D11: =congressman!B150 -> 152 | E11: congressman
B12: 400 | D12: =congressman!B157 -> 159 | E12: congressman
B13: 400 | D13: =congressman!B235 -> 240 | E13: congressman
B14: 400 | D14: =congressman!#REF! -> #REF! | E14: congressman
B15: 400 | D15: =congressman!B51 -> 51 | E15: congressman
B16: 400 | D16: =congressman!B59 -> 59 | E16: congressman
B17: 400 | D17: =congressman!B170 -> 174 | E17: congressman
B18: 400 | D18: =congressman!B179 -> 183 | E18: congressman
B19: 400 | D19: =congressman!B83 -> 84 | E19: congressman
B20: 400 | D20: =congressman!B243 -> 250 | E20: congressman
B21: 400 | D21: =congressman!B189 -> 193 | E21: congressman
B22: 400 | D22: =congressman!B193 -> 197 | E22: congressman
B23: 400 | D23: =congressman!B197 -> 201 | E23: congressman
B24: 400 | D24: =congressman!B199 -> 204 | E24: congressman
B25: 400 | D25: =congressman!B272 -> 280 | E25: congressman
B26: 400 | D26: =congressman!B203 -> 208 | E26: congressman
B27: 400 | D27: =congressman!B254 -> 261 | E27: congressman
B28: 400 | D28: =congressman!B221 -> 226 | E28: congressman
B29: 401 | C29: 군인사법 개정안 발의(박찬주 방지법) | D29: =congressman!B15 -> 14 | E29: congressman | H29: http://likms.assembly.go.kr/bill/billDetail.do?billId=PRC_R1V7Y0X8B1F0H1Q7I1K6P0E8F7K4S7
B30: 401 | D30: =congressman!B31 -> 30 | E30: congressman
B31: 401 | D31: =congressman!B64 -> 64 | E31: congressman
B32: 401 | D32: =congressman!#REF! -> #REF! | E32: congressman
B33: 401 | D33: =congressman!B70 -> 71 | E33: congressman
B34: 401 | D34: =congressman!B73 -> 74 | E34: congressman
B35: 401 | D35: =congressman!B81 -> 82 | E35: congressman
B36: 401 | D36: =congressman!B83 -> 84 | E36: congressman
B37: 401 | D37: =congressman!B91 -> 92 | E37: congressman
B38: 401 | D38: =congressman!B115 -> 116 | E38: congressman

Sheet speciallaws
B2: no | C2: title | D2: memberid | E2: member_sheet | F2: opinion | G2: detail | H2: web
B3: 300 | C3: 최순실 재산몰수 특별법 발의 | D3: =congressman!B68 -> 68 | E3: congressman | H3: http://likms.assembly.go.kr/bill/billDetail.do?billId=PRC_W1L7Z0D7Z2V7L1C1I2N3M0W7C0A3E4
B4: 300 | D4: =congressman!B3 -> 1 | E4: congressman
B5: 300 | D5: =congressman!B5 -> 3 | E5: congressman
B6: 300 | D6: =congressman!B6 -> 4 | E6: congressman
B7: 300 | D7: =congressman!B7 -> 5 | E7: congressman
B8: 300 | D8: =congressman!B8 -> 6 | E8: congressman
B9: 300 | D9: =congressman!B10 -> 8 | E9: congressman
B10: 300 | D10: =congressman!#REF! -> #REF! | E10: congressman
B11: 300 | D11: =congressman!B225 -> 230 | E11: congressman
B12: 300 | D12: =congressman!B11 -> 10 | E12: congressman
B13: 300 | D13: =congressman!B226 -> 231 | E13: congressman
B14: 300 | D14: =congressman!B227 -> 232 | E14: congressman
B15: 300 | D15: =congressman!B12 -> 11 | E15: congressman
B16: 300 | D16: =congressman!B13 -> 12 | E16: congressman
B17: 300 | D17: =congressman!B14 -> 13 | E17: congressman
B18: 300 | D18: =congressman!B15 -> 14 | E18: congressman
B19: 300 | D19: =congressman!B16 -> 15 | E19: congressman
B20: 300 | D20: =congressman!B18 -> 17 | E20: congressman
B21: 300 | D21: =congressman!B19 -> 18 | E21: congressman
B22: 300 | D22: =congressman!B138 -> 140 | E22: congressman
B23: 300 | D23: =congressman!B231 -> 236 | E23: congressman
B24: 300 | D24: =congressman!B20 -> 19 | E24: congressman
B25: 300 | D25: =congressman!B21 -> 20 | E25: congressman
B26: 300 | D26: =congressman!B23 -> 22 | E26: congressman
B27: 300 | D27: =congressman!B24 -> 23 | E27: congressman
B28: 300 | D28: =congressman!B281 -> 289 | E28: congressman
B29: 300 | D29: =congressman!B25 -> 24 | E29: congressman
B30: 300 | D30: =congressman!B288 -> 296 | E30: congressman
B31: 300 | D31: =congressman!B27 -> 26 | E31: congressman
B32: 300 | D32: =congressman!B28 -> 27 | E32: congressman
B33: 300 | D33: =congressman!B29 -> 28 | E33: congressman
B34: 300 | D34: =congressman!B30 -> 29 | E34: congressman
B35: 300 | D35: =congressman!B31 -> 30 | E35: congressman
B36: 300 | D36: =congressman!B33 -> 32 | E36: congressman
B37: 300 | D37: =congressman!B34 -> 33 | E37: congressman
B38: 300 | D38: =congressman!B282 -> 290 | E38: congressman
B39: 300 | D39: =congressman!B37 -> 36 | E39: congressman
B40: 300 | D40: =congressman!B38 -> 37 | E40: congressman
B41: 300 | D41: =congressman!B39 -> 38 | E41: congressman
...

Sheet normalgroups
B2: no | C2: title | D2: memberid | E2: member_sheet | F2: opinion | G2: detail | H2: web | I2: name
B3: 1 | C3: 환경노동위원회 | D3: 118 | E3: congressman | H3: http://environment.na.go.kr | I3: =VLOOKUP(D3,congressman!$B$3:$C$290,2) -> 홍영표
B4: 1 | D4: =congressman!B116 -> 117 | E4: congressman | I4: =VLOOKUP(D4,congressman!$B$3:$C$290,2) -> 한정애
B5: 1 | D5: =congressman!B201 -> 206 | E5: congressman | I5: =VLOOKUP(D5,congressman!$B$3:$C$290,2) -> 임이자
B6: 1 | D6: =congressman!B229 -> 234 | E6: congressman | I6: =VLOOKUP(D6,congressman!$B$3:$C$290,2) -> 김삼화
B7: 1 | D7: =congressman!B278 -> 286 | E7: congressman | I7: =VLOOKUP(D7,congressman!$B$3:$C$290,2) -> 하태경
B8: 1 | D8: 1 | E8: congressman | I8: =VLOOKUP(D8,congressman!$B$3:$C$290,2) -> 강병원
B9: 1 | D9: =congressman!B55 -> 55 | E9: congressman | I9: =VLOOKUP(D9,congressman!$B$3:$C$290,2) -> 서형수
B10: 1 | D10: =congressman!B61 -> 61 | E10: congressman | I10: =VLOOKUP(D10,congressman!$B$3:$C$290,2) -> 송옥주
B11: 1 | D11: =congressman!B64 -> 64 | E11: congressman | I11: =VLOOKUP(D11,congressman!$B$3:$C$290,2) -> 신창현
B12: 1 | D12: =congressman!B86 -> 87 | E12: congressman | I12: =VLOOKUP(D12,congressman!$B$3:$C$290,2) -> 이용득
B13: 1 | D13: =congressman!B153 -> 155 | E13: congressman | I13: =VLOOKUP(D13,congressman!$B$3:$C$290,2) -> 문진국
B14: 1 | D14: =congressman!#REF! -> #REF! | E14: congressman | I14: =VLOOKUP(D14,congressman!$B$3:$C$290,2) -> #REF!
B15: 1 | D15: =congressman!B167 -> 171 | E15: congressman | I15: =VLOOKUP(D15,congressman!$B$3:$C$290,2) -> 신보라
B16: 1 | D16: =congressman!B202 -> 207 | E16: congressman | I16: =VLOOKUP(D16,congressman!$B$3:$C$290,2) -> 장석춘
B17: 1 | D17: =congressman!B244 -> 251 | E17: congressman | I17: =VLOOKUP(D17,congressman!$B$3:$C$290,2) -> 이상돈
B18: 1 | D18: =congressman!B285 -> 293 | E18: congressman | I18: =VLOOKUP(D18,congressman!$B$3:$C$290,2) -> 이정미
B19: 2 | C19: 외교통일위원회 | D19: 66 | E19: congressman | H19: http://uft.na.go.kr | I19: =VLOOKUP(D19,congressman!$B$3:$C$290,2) -> 심재권
B20: 2 | D20: =congressman!B11 -> 10 | E20: congressman | I20: =VLOOKUP(D20,congressman!$B$3:$C$290,2) -> 김경협
B21: 2 | D21: =congressman!B180 -> 184 | E21: congressman | I21: =VLOOKUP(D21,congressman!$B$3:$C$290,2) -> 윤영석
B22: 2 | D22: =congressman!B249 -> 256 | E22: congressman | I22: =VLOOKUP(D22,congressman!$B$3:$C$290,2) -> 이태규
B23: 2 | D23: =congressman!B274 -> 282 | E23: congressman | I23: =VLOOKUP(D23,congressman!$B$3:$C$290,2) -> 정양석
B24: 2 | D24: 2 | E24: congressman | I24: =VLOOKUP(D24,congressman!$B$3:$C$290,2) -> 강창일
B25: 2 | D25: =congressman!B37 -> 36 | E25: congressman | I25: =VLOOKUP(D25,congressman!$B$3:$C$290,2) -> 문희상
B26: 2 | D26: =congressman!B43 -> 43 | E26: congressman | I26: =VLOOKUP(D26,congressman!$B$3:$C$290,2) -> 박병석
B27: 2 | D27: =congressman!B75 -> 76 | E27: congressman | I27: =VLOOKUP(D27,congressman!$B$3:$C$290,2) -> 원혜영
B28: 2 | D28: =congressman!B85 -> 86 | E28: congressman | I28: =VLOOKUP(D28,congressman!$B$3:$C$290,2) -> 이석현
B29: 2 | D29: =congressman!B36 -> 35 | E29: congressman | I29: =VLOOKUP(D29,congressman!$B$3:$C$290,2) -> 이수혁
B30: 2 | D30: =congressman!B88 -> 89 | E30: congressman | I30: =VLOOKUP(D30,congressman!$B$3:$C$290,2) -> 이인영
B31: 2 | D31: =congressman!B114 -> 115 | E31: congressman | I31: =VLOOKUP(D31,congressman!$B$3:$C$290,2) -> 추미애
B32: 2 | D32: =congressman!B163 -> 167 | E32: congressman | I32: =VLOOKUP(D32,congressman!$B$3:$C$290,2) -> 서청원
B33: 2 | D33: =congressman!B174 -> 178 | E33: congressman | I33: =VLOOKUP(D33,congressman!$B$3:$C$290,2) -> 원유철
B34: 2 | D34: =congressman!B175 -> 179 | E34: congressman | I34: =VLOOKUP(D34,congressman!$B$3:$C$290,2) -> 유기준
B35: 2 | D35: =congressman!B179 -> 183 | E35: congressman | I35: =VLOOKUP(D35,congressman!$B$3:$C$290,2) -> 윤상현
B36: 2 | D36: =congressman!B195 -> 199 | E36: congressman | I36: =VLOOKUP(D36,congressman!$B$3:$C$290,2) -> 이주영
B37: 2 | D37: =congressman!B215 -> 220 | E37: congressman | I37: =VLOOKUP(D37,congressman!$B$3:$C$290,2) -> 최경환
B38: 2 | D38: =congressman!B221 -> 226 | E38: congressman | I38: =VLOOKUP(D38,congressman!$B$3:$C$290,2) -> 홍문종
B39: 2 | D39: =congressman!B235 -> 240 | E39: congressman | I39: =VLOOKUP(D39,congressman!$B$3:$C$290,2) -> 박주선
B40: 2 | D40: =congressman!B262 -> 270 | E40: congressman | I40: =VLOOKUP(D40,congressman!$B$3:$C$290,2) -> 김무성
B41: 3 | C41: 국회운영위원회 | D41: =congressman!B207 -> 212 | E41: congressman | H41: http://steering.na.go.kr/site | I41: =VLOOKUP(D41,congressman!$B$3:$C$290,2) -> 정우택
...

Sheet specialgroups
B2: no | C2: title | D2: memberid | E2: member_sheet | F2: opinion | G2: detail | H2: web
B3: 102 | C3: 헌법개정 특별위원회 | D3: =congressman!B4 -> 2 | E3: congressman
B4: 102 | D4: =congressman!B7 -> 5 | E4: congressman
B5: 102 | D5: =congressman!B11 -> 10 | E5: congressman
B6: 102 | D6: =congressman!B25 -> 24 | E6: congressman
B7: 102 | D7: =congressman!B43 -> 43 | E7: congressman
B8: 102 | D8: =congressman!B52 -> 52 | E8: congressman
B9: 102 | D9: =congressman!B54 -> 54 | E9: congressman
B10: 102 | D10: =congressman!B84 -> 85 | E10: congressman
B11: 102 | D11: =congressman!B88 -> 89 | E11: congressman
B12: 102 | D12: =congressman!B89 -> 90 | E12: congressman
B13: 102 | D13: =congressman!B90 -> 91 | E13: congressman
B14: 102 | D14: =congressman!B99 -> 100 | E14: congressman
B15: 102 | D15: =congressman!B100 -> 101 | E15: congressman
B16: 102 | D16: =congressman!B110 -> 111 | E16: congressman
B17: 102 | D17: =congressman!B113 -> 114 | E17: congressman
B18: 102 | D18: =congressman!B123 -> 124 | E18: congressman
B19: 102 | D19: =congressman!B139 -> 141 | E19: congressman
B20: 102 | D20: =congressman!B145 -> 147 | E20: congressman
B21: 102 | D21: =congressman!B164 -> 168 | E21: congressman
B22: 102 | D22: =congressman!B181 -> 185 | E22: congressman
B23: 102 | D23: =congressman!B194 -> 198 | E23: congressman
B24: 102 | D24: =congressman!B195 -> 199 | E24: congressman
B25: 102 | D25: =congressman!B197 -> 201 | E25: congressman
B26: 102 | D26: =congressman!#REF! -> #REF! | E26: congressman
B27: 102 | D27: =congressman!B206 -> 211 | E27: congressman
B28: 102 | D28: =congressman!B216 -> 221 | E28: congressman
B29: 102 | D29: =congressman!B223 -> 228 | E29: congressman
B30: 102 | D30: =congressman!B226 -> 231 | E30: congressman
B31: 102 | D31: =congressman!#REF! -> #REF! | E31: congressman
B32: 102 | D32: =congressman!B244 -> 251 | E32: congressman
B33: 102 | D33: =congressman!B257 -> 264 | E33: congressman
B34: 102 | D34: =congressman!B270 -> 278 | E34: congressman
B35: 102 | D35: =congressman!B278 -> 286 | E35: congressman
B36: 102 | D36: =congressman!B282 -> 290 | E36: congressman
B37: 103 | C37: 미래창조과학방송통신위원회 | D37: =congressman!B6 -> 4 | E37: congressman
B38: 103 | D38: =congressman!B19 -> 18 | E38: congressman
B39: 103 | D39: =congressman!B32 -> 31 | E39: congressman
B40: 103 | D40: =congressman!B51 -> 51 | E40: congressman
B41: 103 | D41: =congressman!B54 -> 54 | E41: congressman
...

Sheet groups
B2: no | C2: title | D2: detail | E2: office | F2: email | G2: twitter | H2: facebook | I2: kakao | J2: instagram | K2: youtube | L2: web | M2: blog | N2: café | O2: cyworld | P2: sponsor
B3: 1 | C3: 더불어민주당 | E3: 1577-7667 | G3: TheMinjoo_Kr | H3: 163693313660505 | J3: theminjoo | K3: https://www.youtube.com/user/minjootv | L3: http://theminjoo.kr | M3: http://blog.naver.com/yesminjoo | P3: 1001
B4: 2 | C4: 자유한국당 | E4: 02-3786-3000 | G4: liberty_kr | H4: 295775117138819 | I4: libertykorea | J4: libertykorea | K4: https://www.youtube.com/c/%EC%9E%90%EC%9C%A0%ED%95%9C%EA%B5%AD%EB%8B%B9 | L4: http://www.libertykoreaparty.kr | M4: http://blog.libertykoreaparty.kr/ | P4: 1002
B5: 3 | C5: 바른미래당 | E5: 02-2070-5600 | G5: bareunmiraedang | H5: 1651975401769490 | J5: peopleparty21 | K5: https://www.youtube.com/channel/UCpnetwDnXC5eFlQhjmbv12g | L5: http://bareunmirae.kr/ | P5: 1003
B6: 4 | C6: 민주평화당 | G6: peacesns0206 | H6: 154484148538922 | K6: https://www.youtube.com/channel/UCYKkiLSC7roybcyd5eVPl9g | L6: http://peaceparty.co.kr/ | P6: 1004
B7: 5 | C7: 정의당 | E7: 02-2038-0103 | G7: kr_justice | H7: 512722405481009 | I7: jbhyendx | J7: justice_party | K7: https://www.youtube.com/channel/UC4KdOy46f0HCJBqTiq7MLPg | L7: http://www.justice21.org | M7: http://blog.naver.com/justiceparty | P7: 1005
B8: 6 | C8: 대한애국당 | H8: 1869948593320390 | J8: gkpp0815 | K8: https://www.youtube.com/channel/UC5Ys11G8I-ULCXm6cNowB1w | L8: http://kpparty.kr/ | N8: https://m.cafe.naver.com/kppmembers.cafe | P8: 1006
B9: 7 | C9: 민중당 | E9: 02-6933-0012 | F9: theminjungparty@gmail.com | H9: 1643827669215080 | I9: _nldxexl | J9: minjungparty | K9: https://www.youtube.com/channel/UCD2FurCIhOsG3FsTM1-jirA | L9: http://minjungparty.com/main/ | P9: 1007
B10: 8 | C10: 무소속 | P10: 9001
